<?xml version="1.0" ?>
<!-- =================================================================================== -->
<!-- |    This document was autogenerated by xacro from /home/ehuang/catkin_ws/src/apc_ros/apc_description/urdf/crichton/crichton.urdf.xacro | -->
<!-- |    EDITING THIS FILE BY HAND IS NOT RECOMMENDED                                 | -->
<!-- =================================================================================== -->
<robot name="crichton" xmlns:xacro="http://www.ros.org/wiki/xacro">
  <!-- Include APC decriptions for LWA4 and SDH -->
  <material name="Schunk_LightGrey">
    <color rgba="0.7 0.7 0.7 1.0"/>
  </material>
  <material name="Schunk_DarkGrey">
    <color rgba="0.4 0.4 0.4 1.0"/>
  </material>
  <material name="Schunk_Black">
    <color rgba="0.05 0.05 0.05 1.0"/>
  </material>
  <material name="Schunk_DarkGolden">
    <color rgba="0.4 0.4 0.3 1.0"/>
  </material>
  <material name="Schunk_Blue">
    <color rgba="0.0 0.0 0.8 1.0"/>
  </material>
  <!-- Math constants -->
  <!-- Crichton origin. -->
  <link name="crichton_origin"/>
  <!-- Assemble Crichton torso -->
  <link name="crichton_vertical_support">
    <inertial>
      <origin rpy="0 0 0" xyz="0.0 0.0 0.0"/>
      <mass value="5.0"/>
      <inertia ixx="1" ixy="0.0" ixz="0.0" iyy="1" iyz="0.0" izz="1"/>
    </inertial>
    <visual>
      <origin rpy="0 0 0" xyz="-0.45 -0.45 0.0"/>
      <geometry>
        <mesh filename="package://apc_description/meshes/lwa4d_torso/vertical_support.dae" scale="1 1 1"/>
      </geometry>
    </visual>
    <collision>
      <origin rpy="0 0 0" xyz="-0.45 -0.45 0.0"/>
      <geometry>
        <mesh filename="package://apc_description/meshes/lwa4d_torso/vertical_support.dae" scale="1 1 1"/>
      </geometry>
    </collision>
  </link>
  <joint name="crichton_base_joint" type="fixed">
    <origin rpy="0 0 0" xyz="0 0 0"/>
    <parent link="crichton_origin"/>
    <child link="crichton_vertical_support"/>
  </joint>
  <link name="crichton_middle_support">
    <inertial>
      <origin rpy="0 0 0" xyz="0.0 0.0 0.0"/>
      <mass value="5.0"/>
      <inertia ixx="1" ixy="0.0" ixz="0.0" iyy="1" iyz="0.0" izz="1"/>
    </inertial>
    <visual>
      <geometry>
        <mesh filename="package://apc_description/meshes/lwa4d_torso/middle_support.dae" scale="1 1 1"/>
      </geometry>
    </visual>
    <collision>
      <geometry>
        <mesh filename="package://apc_description/meshes/lwa4d_torso/middle_support.dae" scale="1 1 1"/>
      </geometry>
    </collision>
  </link>
  <joint name="crichton_torso_joint" type="revolute">
    <origin rpy="0 0 0" xyz="0 0 1.23"/>
    <parent link="crichton_vertical_support"/>
    <child link="crichton_middle_support"/>
    <axis xyz="0 0 -1"/>
    <dynamics damping="5"/>
    <limit effort="20.1" lower="-1.8" upper="1.8" velocity="2.0"/>
  </joint>
  <!-- Assemble Crichton arms -->
  <link name="crichton_left_0_link">
    <inertial>
      <origin rpy="0 0 0" xyz="0 0 0"/>
      <mass value="1.0"/>
      <inertia ixx="0.01" ixy="0" ixz="0" iyy="0.01" iyz="0" izz="0.01"/>
    </inertial>
    <visual>
      <origin rpy="0 0 0" xyz="0 0 0"/>
      <geometry>
        <cylinder length="0.03" radius="0.045"/>
      </geometry>
      <material name="Schunk/Black"/>
    </visual>
    <collision>
      <origin rpy="0 0 0" xyz="0 0 0"/>
      <geometry>
        <cylinder length="0.03" radius="0.045"/>
      </geometry>
    </collision>
  </link>
  <link name="crichton_left_1_link">
    <inertial>
      <origin rpy="0 0 0" xyz="0 0 0"/>
      <!--mass value="5.9907"/-->
      <mass value="2.0"/>
      <inertia ixx="0.01" ixy="0" ixz="0" iyy="0.01" iyz="0" izz="0.01"/>
    </inertial>
    <visual>
      <origin rpy="0 0 0" xyz="0 0 0"/>
      <geometry>
        <mesh filename="package://apc_description/meshes/lwa4d/arm_1_link.dae"/>
      </geometry>
      <material name="Schunk_LightGrey">
        <color rgba="0.7 0.7 0.7 1.0"/>
      </material>
    </visual>
    <collision>
      <origin rpy="0 0 0" xyz="0 0 0"/>
      <geometry>
        <mesh filename="package://apc_description/meshes/lwa4d/arm_1_link.dae"/>
      </geometry>
    </collision>
  </link>
  <link name="crichton_left_2_link">
    <inertial>
      <origin rpy="0 0 0" xyz="0 0 0"/>
      <mass value="2.0"/>
      <inertia ixx="0.03" ixy="0" ixz="0" iyy="0.03" iyz="0" izz="0.03"/>
    </inertial>
    <visual>
      <origin rpy="0 0 0" xyz="0 0 0"/>
      <geometry>
        <mesh filename="package://apc_description/meshes/lwa4d/arm_2_link.dae"/>
      </geometry>
      <material name="Schunk_Black"/>
    </visual>
    <collision>
      <origin rpy="0 0 0" xyz="0 0 0"/>
      <geometry>
        <mesh filename="package://apc_description/meshes/lwa4d/arm_2_link.dae"/>
      </geometry>
    </collision>
  </link>
  <link name="crichton_left_3_link">
    <inertial>
      <origin rpy="0 0 0" xyz="0 0 0"/>
      <mass value="2.0"/>
      <inertia ixx="0.03" ixy="0" ixz="0" iyy="0.03" iyz="0" izz="0.03"/>
    </inertial>
    <visual>
      <origin rpy="0 0 0" xyz="0 0 0"/>
      <geometry>
        <mesh filename="package://apc_description/meshes/lwa4d/arm_3_link.dae"/>
      </geometry>
      <material name="Schunk_LightGrey"/>
    </visual>
    <collision>
      <origin rpy="0 0 0" xyz="0 0 0"/>
      <geometry>
        <mesh filename="package://apc_description/meshes/lwa4d/arm_3_link.dae"/>
      </geometry>
    </collision>
  </link>
  <link name="crichton_left_4_link">
    <inertial>
      <origin rpy="0 0 0" xyz="0 0 0"/>
      <mass value="2.0"/>
      <inertia ixx="0.03" ixy="0" ixz="0" iyy="0.03" iyz="0" izz="0.03"/>
    </inertial>
    <visual>
      <origin rpy="0 0 0" xyz="0 0 0"/>
      <geometry>
        <mesh filename="package://apc_description/meshes/lwa4d/arm_4_link.dae"/>
      </geometry>
      <material name="Schunk_Black"/>
    </visual>
    <collision>
      <origin rpy="0 0 0" xyz="0 0 0"/>
      <geometry>
        <mesh filename="package://apc_description/meshes/lwa4d/arm_4_link.dae"/>
      </geometry>
    </collision>
  </link>
  <link name="crichton_left_5_link">
    <inertial>
      <origin rpy="0 0 0" xyz="0 0 0"/>
      <mass value="2.313272"/>
      <inertia ixx="0.03" ixy="0" ixz="0" iyy="0.03" iyz="0" izz="0.03"/>
    </inertial>
    <visual>
      <origin rpy="0 0 0" xyz="0 0 0"/>
      <geometry>
        <mesh filename="package://apc_description/meshes/lwa4d/arm_5_link_phys.dae"/>
      </geometry>
      <material name="Schunk_LightGrey"/>
    </visual>
    <collision>
      <origin rpy="0 0 0" xyz="0 0 0"/>
      <geometry>
        <mesh filename="package://apc_description/meshes/lwa4d/arm_5_link_phys.dae"/>
      </geometry>
    </collision>
  </link>
  <link name="crichton_left_6_link">
    <inertial>
      <origin rpy="0 0 0" xyz="0 0 0"/>
      <mass value="2.057856"/>
      <inertia ixx="0.01" ixy="0" ixz="0" iyy="0.01" iyz="0" izz="0.01"/>
    </inertial>
    <visual>
      <origin rpy="0 0 0" xyz="0 0 0"/>
      <geometry>
        <mesh filename="package://apc_description/meshes/lwa4d/arm_6_link.dae"/>
      </geometry>
      <material name="Schunk_Black"/>
    </visual>
    <collision>
      <origin rpy="0 0 0" xyz="0 0 0"/>
      <geometry>
        <mesh filename="package://apc_description/meshes/lwa4d/arm_6_link.dae"/>
      </geometry>
    </collision>
  </link>
  <link name="crichton_left_7_link">
    <inertial>
      <origin rpy="0 0 0" xyz="0 0 0"/>
      <mass value="1.120198"/>
      <inertia ixx="0.01" ixy="0" ixz="0" iyy="0.01" iyz="0" izz="0.01"/>
    </inertial>
    <visual>
      <origin rpy="0 0 0" xyz="0 0 0"/>
      <geometry>
        <mesh filename="package://apc_description/meshes/lwa4d/arm_7_FT_tool_changers_link.dae"/>
      </geometry>
      <material name="Schunk_LightGrey"/>
    </visual>
    <collision>
      <origin rpy="0 0 0" xyz="0 0 0"/>
      <geometry>
        <mesh filename="package://apc_description/meshes/lwa4d/arm_7_FT_tool_changers_link.dae"/>
      </geometry>
    </collision>
  </link>
  <joint name="crichton_left_0_joint" type="fixed">
    <origin rpy="0 0 3.141592653" xyz="0 0 0"/>
    <parent link="crichton_middle_support"/>
    <child link="crichton_left_0_link"/>
  </joint>
  <joint name="crichton_left_1_joint" type="revolute">
    <!-- <origin xyz="0 0.1375 0" rpy="1.57 3.1416 0"/> -->
    <origin rpy="1.57 3.1416 0" xyz="0 0.12 0"/>
    <parent link="crichton_left_0_link"/>
    <child link="crichton_left_1_link"/>
    <axis xyz="0 0 1"/>
    <dynamics damping="10"/>
    <limit effort="370" lower="-3.14" upper="3.14" velocity="2.0"/>
  </joint>
  <joint name="crichton_left_2_joint" type="revolute">
    <origin rpy="-1.57 0 0" xyz="0 0 -0.18"/>
    <parent link="crichton_left_1_link"/>
    <child link="crichton_left_2_link"/>
    <axis xyz="0 0 -1"/>
    <dynamics damping="10"/>
    <limit effort="370" lower="-1.97" upper="1.97" velocity="2.0"/>
  </joint>
  <joint name="crichton_left_3_joint" type="revolute">
    <origin rpy="1.57 0 0" xyz="0 0 0"/>
    <parent link="crichton_left_2_link"/>
    <child link="crichton_left_3_link"/>
    <axis xyz="0 0 1"/>
    <dynamics damping="5"/>
    <limit effort="176" lower="-3.14" upper="3.14" velocity="2.0"/>
  </joint>
  <joint name="crichton_left_4_joint" type="revolute">
    <origin rpy="-1.57 0 0" xyz="0 0 -0.328"/>
    <parent link="crichton_left_3_link"/>
    <child link="crichton_left_4_link"/>
    <axis xyz="0 0 -1"/>
    <dynamics damping="5"/>
    <limit effort="176" lower="-2.08208" upper="2.08208" velocity="2.0"/>
  </joint>
  <joint name="crichton_left_5_joint" type="revolute">
    <origin rpy="1.57 0 0" xyz="0 0 0"/>
    <parent link="crichton_left_4_link"/>
    <child link="crichton_left_5_link"/>
    <axis xyz="0 0 1"/>
    <dynamics damping="5"/>
    <limit effort="41.6" lower="-3.14" upper="3.14" velocity="2.0"/>
  </joint>
  <joint name="crichton_left_6_joint" type="revolute">
    <origin rpy="1.57 0 0" xyz="0 0 -0.323"/>
    <parent link="crichton_left_5_link"/>
    <child link="crichton_left_6_link"/>
    <axis xyz="0 0 -1"/>
    <dynamics damping="5"/>
    <limit effort="20.1" lower="-1.8" upper="1.8" velocity="2.0"/>
  </joint>
  <joint name="crichton_left_7_joint" type="revolute">
    <origin rpy="-1.57 0 0" xyz="0 -0.1672 0"/>
    <parent link="crichton_left_6_link"/>
    <child link="crichton_left_7_link"/>
    <axis xyz="0 0 -1"/>
    <dynamics damping="5"/>
    <limit effort="9.6" lower="-3.14" upper="3.14" velocity="2.0"/>
  </joint>
  <gazebo reference="crichton_left_base_link">
    <gravity>true</gravity>
    <self_collide>false</self_collide>
    <material value="Schunk/Black"/>
  </gazebo>
  <gazebo reference="crichton_left_1_link">
    <gravity>true</gravity>
    <self_collide>false</self_collide>
    <material value="Schunk/LightGrey"/>
  </gazebo>
  <gazebo reference="crichton_left_2_link">
    <gravity>true</gravity>
    <self_collide>false</self_collide>
    <material value="Schunk/Black"/>
  </gazebo>
  <gazebo reference="crichton_left_3_link">
    <gravity>true</gravity>
    <self_collide>false</self_collide>
    <material value="Schunk/LightGrey"/>
  </gazebo>
  <gazebo reference="crichton_left_4_link">
    <gravity>true</gravity>
    <self_collide>false</self_collide>
    <material value="Schunk/Black"/>
  </gazebo>
  <gazebo reference="crichton_left_5_link">
    <gravity>true</gravity>
    <self_collide>false</self_collide>
    <material value="Schunk/LightGrey"/>
  </gazebo>
  <gazebo reference="crichton_left_6_link">
    <gravity>true</gravity>
    <self_collide>false</self_collide>
    <material value="Schunk/Black"/>
  </gazebo>
  <gazebo reference="crichton_left_7_link">
    <gravity>true</gravity>
    <self_collide>false</self_collide>
    <material value="Schunk/LightGrey"/>
  </gazebo>
  <transmission name="crichton_left_1_trans">
    <type>transmission_interface/SimpleTransmission</type>
    <joint name="crichton_left_1_joint">
      <hardwareInterface>PositionJointInterface</hardwareInterface>
      <hardwareInterface>VelocityJointInterface</hardwareInterface>
    </joint>
    <actuator name="crichton_left_1_motor">
      <mechanicalReduction>1</mechanicalReduction>
    </actuator>
  </transmission>
  <transmission name="crichton_left_2_trans">
    <type>transmission_interface/SimpleTransmission</type>
    <joint name="crichton_left_2_joint">
      <hardwareInterface>PositionJointInterface</hardwareInterface>
      <hardwareInterface>VelocityJointInterface</hardwareInterface>
    </joint>
    <actuator name="crichton_left_2_motor">
      <mechanicalReduction>1</mechanicalReduction>
    </actuator>
  </transmission>
  <transmission name="crichton_left_3_trans">
    <type>transmission_interface/SimpleTransmission</type>
    <joint name="crichton_left_3_joint">
      <hardwareInterface>PositionJointInterface</hardwareInterface>
      <hardwareInterface>VelocityJointInterface</hardwareInterface>
    </joint>
    <actuator name="crichton_left_3_motor">
      <mechanicalReduction>1</mechanicalReduction>
    </actuator>
  </transmission>
  <transmission name="crichton_left_4_trans">
    <type>transmission_interface/SimpleTransmission</type>
    <joint name="crichton_left_4_joint">
      <hardwareInterface>PositionJointInterface</hardwareInterface>
      <hardwareInterface>VelocityJointInterface</hardwareInterface>
    </joint>
    <actuator name="crichton_left_4_motor">
      <mechanicalReduction>1</mechanicalReduction>
    </actuator>
  </transmission>
  <transmission name="crichton_left_5_trans">
    <type>transmission_interface/SimpleTransmission</type>
    <joint name="crichton_left_5_joint">
      <hardwareInterface>PositionJointInterface</hardwareInterface>
      <hardwareInterface>VelocityJointInterface</hardwareInterface>
    </joint>
    <actuator name="crichton_left_5_motor">
      <mechanicalReduction>1</mechanicalReduction>
    </actuator>
  </transmission>
  <transmission name="crichton_left_6_trans">
    <type>transmission_interface/SimpleTransmission</type>
    <joint name="crichton_left_6_joint">
      <hardwareInterface>PositionJointInterface</hardwareInterface>
      <hardwareInterface>VelocityJointInterface</hardwareInterface>
    </joint>
    <actuator name="crichton_left_6_motor">
      <mechanicalReduction>1</mechanicalReduction>
    </actuator>
  </transmission>
  <transmission name="crichton_left_7_trans">
    <type>transmission_interface/SimpleTransmission</type>
    <joint name="crichton_left_7_joint">
      <hardwareInterface>PositionJointInterface</hardwareInterface>
      <hardwareInterface>VelocityJointInterface</hardwareInterface>
    </joint>
    <actuator name="crichton_left_7_motor">
      <mechanicalReduction>1</mechanicalReduction>
    </actuator>
  </transmission>
  <link name="crichton_right_0_link">
    <inertial>
      <origin rpy="0 0 0" xyz="0 0 0"/>
      <mass value="1.0"/>
      <inertia ixx="0.01" ixy="0" ixz="0" iyy="0.01" iyz="0" izz="0.01"/>
    </inertial>
    <visual>
      <origin rpy="0 0 0" xyz="0 0 0"/>
      <geometry>
        <cylinder length="0.03" radius="0.045"/>
      </geometry>
      <material name="Schunk/Black"/>
    </visual>
    <collision>
      <origin rpy="0 0 0" xyz="0 0 0"/>
      <geometry>
        <cylinder length="0.03" radius="0.045"/>
      </geometry>
    </collision>
  </link>
  <link name="crichton_right_1_link">
    <inertial>
      <origin rpy="0 0 0" xyz="0 0 0"/>
      <!--mass value="5.9907"/-->
      <mass value="2.0"/>
      <inertia ixx="0.01" ixy="0" ixz="0" iyy="0.01" iyz="0" izz="0.01"/>
    </inertial>
    <visual>
      <origin rpy="0 0 0" xyz="0 0 0"/>
      <geometry>
        <mesh filename="package://apc_description/meshes/lwa4d/arm_1_link.dae"/>
      </geometry>
      <material name="Schunk_LightGrey">
        <color rgba="0.7 0.7 0.7 1.0"/>
      </material>
    </visual>
    <collision>
      <origin rpy="0 0 0" xyz="0 0 0"/>
      <geometry>
        <mesh filename="package://apc_description/meshes/lwa4d/arm_1_link.dae"/>
      </geometry>
    </collision>
  </link>
  <link name="crichton_right_2_link">
    <inertial>
      <origin rpy="0 0 0" xyz="0 0 0"/>
      <mass value="2.0"/>
      <inertia ixx="0.03" ixy="0" ixz="0" iyy="0.03" iyz="0" izz="0.03"/>
    </inertial>
    <visual>
      <origin rpy="0 0 0" xyz="0 0 0"/>
      <geometry>
        <mesh filename="package://apc_description/meshes/lwa4d/arm_2_link.dae"/>
      </geometry>
      <material name="Schunk_Black"/>
    </visual>
    <collision>
      <origin rpy="0 0 0" xyz="0 0 0"/>
      <geometry>
        <mesh filename="package://apc_description/meshes/lwa4d/arm_2_link.dae"/>
      </geometry>
    </collision>
  </link>
  <link name="crichton_right_3_link">
    <inertial>
      <origin rpy="0 0 0" xyz="0 0 0"/>
      <mass value="2.0"/>
      <inertia ixx="0.03" ixy="0" ixz="0" iyy="0.03" iyz="0" izz="0.03"/>
    </inertial>
    <visual>
      <origin rpy="0 0 0" xyz="0 0 0"/>
      <geometry>
        <mesh filename="package://apc_description/meshes/lwa4d/arm_3_link.dae"/>
      </geometry>
      <material name="Schunk_LightGrey"/>
    </visual>
    <collision>
      <origin rpy="0 0 0" xyz="0 0 0"/>
      <geometry>
        <mesh filename="package://apc_description/meshes/lwa4d/arm_3_link.dae"/>
      </geometry>
    </collision>
  </link>
  <link name="crichton_right_4_link">
    <inertial>
      <origin rpy="0 0 0" xyz="0 0 0"/>
      <mass value="2.0"/>
      <inertia ixx="0.03" ixy="0" ixz="0" iyy="0.03" iyz="0" izz="0.03"/>
    </inertial>
    <visual>
      <origin rpy="0 0 0" xyz="0 0 0"/>
      <geometry>
        <mesh filename="package://apc_description/meshes/lwa4d/arm_4_link.dae"/>
      </geometry>
      <material name="Schunk_Black"/>
    </visual>
    <collision>
      <origin rpy="0 0 0" xyz="0 0 0"/>
      <geometry>
        <mesh filename="package://apc_description/meshes/lwa4d/arm_4_link.dae"/>
      </geometry>
    </collision>
  </link>
  <link name="crichton_right_5_link">
    <inertial>
      <origin rpy="0 0 0" xyz="0 0 0"/>
      <mass value="2.313272"/>
      <inertia ixx="0.03" ixy="0" ixz="0" iyy="0.03" iyz="0" izz="0.03"/>
    </inertial>
    <visual>
      <origin rpy="0 0 0" xyz="0 0 0"/>
      <geometry>
        <mesh filename="package://apc_description/meshes/lwa4d/arm_5_link_phys.dae"/>
      </geometry>
      <material name="Schunk_LightGrey"/>
    </visual>
    <collision>
      <origin rpy="0 0 0" xyz="0 0 0"/>
      <geometry>
        <mesh filename="package://apc_description/meshes/lwa4d/arm_5_link_phys.dae"/>
      </geometry>
    </collision>
  </link>
  <link name="crichton_right_6_link">
    <inertial>
      <origin rpy="0 0 0" xyz="0 0 0"/>
      <mass value="2.057856"/>
      <inertia ixx="0.01" ixy="0" ixz="0" iyy="0.01" iyz="0" izz="0.01"/>
    </inertial>
    <visual>
      <origin rpy="0 0 0" xyz="0 0 0"/>
      <geometry>
        <mesh filename="package://apc_description/meshes/lwa4d/arm_6_link.dae"/>
      </geometry>
      <material name="Schunk_Black"/>
    </visual>
    <collision>
      <origin rpy="0 0 0" xyz="0 0 0"/>
      <geometry>
        <mesh filename="package://apc_description/meshes/lwa4d/arm_6_link.dae"/>
      </geometry>
    </collision>
  </link>
  <link name="crichton_right_7_link">
    <inertial>
      <origin rpy="0 0 0" xyz="0 0 0"/>
      <mass value="1.120198"/>
      <inertia ixx="0.01" ixy="0" ixz="0" iyy="0.01" iyz="0" izz="0.01"/>
    </inertial>
    <visual>
      <origin rpy="0 0 0" xyz="0 0 0"/>
      <geometry>
        <mesh filename="package://apc_description/meshes/lwa4d/arm_7_FT_tool_changers_link.dae"/>
      </geometry>
      <material name="Schunk_LightGrey"/>
    </visual>
    <collision>
      <origin rpy="0 0 0" xyz="0 0 0"/>
      <geometry>
        <mesh filename="package://apc_description/meshes/lwa4d/arm_7_FT_tool_changers_link.dae"/>
      </geometry>
    </collision>
  </link>
  <joint name="crichton_right_0_joint" type="fixed">
    <origin rpy="0 0 0.0" xyz="0 0 0"/>
    <parent link="crichton_middle_support"/>
    <child link="crichton_right_0_link"/>
  </joint>
  <joint name="crichton_right_1_joint" type="revolute">
    <!-- <origin xyz="0 0.1375 0" rpy="1.57 3.1416 0"/> -->
    <origin rpy="1.57 3.1416 0" xyz="0 0.12 0"/>
    <parent link="crichton_right_0_link"/>
    <child link="crichton_right_1_link"/>
    <axis xyz="0 0 1"/>
    <dynamics damping="10"/>
    <limit effort="370" lower="-3.14" upper="3.14" velocity="2.0"/>
  </joint>
  <joint name="crichton_right_2_joint" type="revolute">
    <origin rpy="-1.57 0 0" xyz="0 0 -0.18"/>
    <parent link="crichton_right_1_link"/>
    <child link="crichton_right_2_link"/>
    <axis xyz="0 0 -1"/>
    <dynamics damping="10"/>
    <limit effort="370" lower="-1.97" upper="1.97" velocity="2.0"/>
  </joint>
  <joint name="crichton_right_3_joint" type="revolute">
    <origin rpy="1.57 0 0" xyz="0 0 0"/>
    <parent link="crichton_right_2_link"/>
    <child link="crichton_right_3_link"/>
    <axis xyz="0 0 1"/>
    <dynamics damping="5"/>
    <limit effort="176" lower="-3.14" upper="3.14" velocity="2.0"/>
  </joint>
  <joint name="crichton_right_4_joint" type="revolute">
    <origin rpy="-1.57 0 0" xyz="0 0 -0.328"/>
    <parent link="crichton_right_3_link"/>
    <child link="crichton_right_4_link"/>
    <axis xyz="0 0 -1"/>
    <dynamics damping="5"/>
    <limit effort="176" lower="-2.08208" upper="2.08208" velocity="2.0"/>
  </joint>
  <joint name="crichton_right_5_joint" type="revolute">
    <origin rpy="1.57 0 0" xyz="0 0 0"/>
    <parent link="crichton_right_4_link"/>
    <child link="crichton_right_5_link"/>
    <axis xyz="0 0 1"/>
    <dynamics damping="5"/>
    <limit effort="41.6" lower="-3.14" upper="3.14" velocity="2.0"/>
  </joint>
  <joint name="crichton_right_6_joint" type="revolute">
    <origin rpy="1.57 0 0" xyz="0 0 -0.323"/>
    <parent link="crichton_right_5_link"/>
    <child link="crichton_right_6_link"/>
    <axis xyz="0 0 -1"/>
    <dynamics damping="5"/>
    <limit effort="20.1" lower="-1.8" upper="1.8" velocity="2.0"/>
  </joint>
  <joint name="crichton_right_7_joint" type="revolute">
    <origin rpy="-1.57 0 0" xyz="0 -0.1672 0"/>
    <parent link="crichton_right_6_link"/>
    <child link="crichton_right_7_link"/>
    <axis xyz="0 0 -1"/>
    <dynamics damping="5"/>
    <limit effort="9.6" lower="-3.14" upper="3.14" velocity="2.0"/>
  </joint>
  <gazebo reference="crichton_right_base_link">
    <gravity>true</gravity>
    <self_collide>false</self_collide>
    <material value="Schunk/Black"/>
  </gazebo>
  <gazebo reference="crichton_right_1_link">
    <gravity>true</gravity>
    <self_collide>false</self_collide>
    <material value="Schunk/LightGrey"/>
  </gazebo>
  <gazebo reference="crichton_right_2_link">
    <gravity>true</gravity>
    <self_collide>false</self_collide>
    <material value="Schunk/Black"/>
  </gazebo>
  <gazebo reference="crichton_right_3_link">
    <gravity>true</gravity>
    <self_collide>false</self_collide>
    <material value="Schunk/LightGrey"/>
  </gazebo>
  <gazebo reference="crichton_right_4_link">
    <gravity>true</gravity>
    <self_collide>false</self_collide>
    <material value="Schunk/Black"/>
  </gazebo>
  <gazebo reference="crichton_right_5_link">
    <gravity>true</gravity>
    <self_collide>false</self_collide>
    <material value="Schunk/LightGrey"/>
  </gazebo>
  <gazebo reference="crichton_right_6_link">
    <gravity>true</gravity>
    <self_collide>false</self_collide>
    <material value="Schunk/Black"/>
  </gazebo>
  <gazebo reference="crichton_right_7_link">
    <gravity>true</gravity>
    <self_collide>false</self_collide>
    <material value="Schunk/LightGrey"/>
  </gazebo>
  <transmission name="crichton_right_1_trans">
    <type>transmission_interface/SimpleTransmission</type>
    <joint name="crichton_right_1_joint">
      <hardwareInterface>PositionJointInterface</hardwareInterface>
      <hardwareInterface>VelocityJointInterface</hardwareInterface>
    </joint>
    <actuator name="crichton_right_1_motor">
      <mechanicalReduction>1</mechanicalReduction>
    </actuator>
  </transmission>
  <transmission name="crichton_right_2_trans">
    <type>transmission_interface/SimpleTransmission</type>
    <joint name="crichton_right_2_joint">
      <hardwareInterface>PositionJointInterface</hardwareInterface>
      <hardwareInterface>VelocityJointInterface</hardwareInterface>
    </joint>
    <actuator name="crichton_right_2_motor">
      <mechanicalReduction>1</mechanicalReduction>
    </actuator>
  </transmission>
  <transmission name="crichton_right_3_trans">
    <type>transmission_interface/SimpleTransmission</type>
    <joint name="crichton_right_3_joint">
      <hardwareInterface>PositionJointInterface</hardwareInterface>
      <hardwareInterface>VelocityJointInterface</hardwareInterface>
    </joint>
    <actuator name="crichton_right_3_motor">
      <mechanicalReduction>1</mechanicalReduction>
    </actuator>
  </transmission>
  <transmission name="crichton_right_4_trans">
    <type>transmission_interface/SimpleTransmission</type>
    <joint name="crichton_right_4_joint">
      <hardwareInterface>PositionJointInterface</hardwareInterface>
      <hardwareInterface>VelocityJointInterface</hardwareInterface>
    </joint>
    <actuator name="crichton_right_4_motor">
      <mechanicalReduction>1</mechanicalReduction>
    </actuator>
  </transmission>
  <transmission name="crichton_right_5_trans">
    <type>transmission_interface/SimpleTransmission</type>
    <joint name="crichton_right_5_joint">
      <hardwareInterface>PositionJointInterface</hardwareInterface>
      <hardwareInterface>VelocityJointInterface</hardwareInterface>
    </joint>
    <actuator name="crichton_right_5_motor">
      <mechanicalReduction>1</mechanicalReduction>
    </actuator>
  </transmission>
  <transmission name="crichton_right_6_trans">
    <type>transmission_interface/SimpleTransmission</type>
    <joint name="crichton_right_6_joint">
      <hardwareInterface>PositionJointInterface</hardwareInterface>
      <hardwareInterface>VelocityJointInterface</hardwareInterface>
    </joint>
    <actuator name="crichton_right_6_motor">
      <mechanicalReduction>1</mechanicalReduction>
    </actuator>
  </transmission>
  <transmission name="crichton_right_7_trans">
    <type>transmission_interface/SimpleTransmission</type>
    <joint name="crichton_right_7_joint">
      <hardwareInterface>PositionJointInterface</hardwareInterface>
      <hardwareInterface>VelocityJointInterface</hardwareInterface>
    </joint>
    <actuator name="crichton_right_7_motor">
      <mechanicalReduction>1</mechanicalReduction>
    </actuator>
  </transmission>
  <!-- Assemble Crichton hands -->
  <joint name="crichton_left_palm_joint" type="fixed">
    <origin rpy="0 3.141592653 -0.5235987755" xyz="0 0 0"/>
    <parent link="crichton_left_7_link"/>
    <child link="crichton_left_palm_link"/>
  </joint>
  <link name="crichton_left_palm_link">
    <inertial>
      <origin rpy="0 0 0" xyz="0 0 0"/>
      <mass value="1"/>
      <inertia ixx="0.01" ixy="0" ixz="0" iyy="0.01" iyz="0" izz="0.01"/>
    </inertial>
    <visual>
      <origin rpy="0 0 0" xyz="0 0 0"/>
      <geometry>
        <mesh filename="package://apc_description/meshes/sdh/palm.dae"/>
      </geometry>
      <material name="Schunk_LightGrey">
        <color rgba="0.7 0.7 0.7 1.0"/>
      </material>
    </visual>
    <collision>
      <origin rpy="0 0 0" xyz="0 0 0"/>
      <geometry>
        <mesh filename="package://apc_description/meshes/sdh/palm.dae"/>
      </geometry>
    </collision>
  </link>
  <joint name="crichton_left_grasp_joint" type="fixed">
    <origin rpy="0 0 0" xyz="0 0 0.15"/>
    <parent link="crichton_left_palm_link"/>
    <child link="crichton_left_grasp_link"/>
  </joint>
  <link name="crichton_left_grasp_link"/>
  <joint name="crichton_left_tip_joint" type="fixed">
    <origin rpy="0 0 0" xyz="0 0 0.22"/>
    <parent link="crichton_left_palm_link"/>
    <child link="crichton_left_tip_link"/>
  </joint>
  <link name="crichton_left_tip_link"/>
  <joint name="crichton_left_knuckle_joint" type="revolute">
    <!-- <origin xyz="-0.033 -0.01905 0.0745" rpy="0 0 ${-M_PI/2}" /> -->
    <origin rpy="0 0 1.5707963265" xyz="0.033 -0.01905 0.0745"/>
    <parent link="crichton_left_palm_link"/>
    <child link="crichton_left_finger_11_link"/>
    <axis xyz="0 0 1"/>
    <dynamics damping="1"/>
    <limit effort="100" lower="0" upper="1.570796327" velocity="5"/>
  </joint>
  <link name="crichton_left_finger_11_link">
    <inertial>
      <origin rpy="0 0 0" xyz="0 0 0"/>
      <mass value="0.1"/>
      <inertia ixx="0.01" ixy="0" ixz="0" iyy="0.01" iyz="0" izz="0.01"/>
    </inertial>
    <visual>
      <origin rpy="0 0 0" xyz="0 0 0"/>
      <geometry>
        <mesh filename="package://apc_description/meshes/sdh/knuckle.dae"/>
      </geometry>
      <material name="Schunk_LightGrey"/>
    </visual>
    <collision>
      <origin rpy="0 0 0" xyz="0 0 0"/>
      <geometry>
        <mesh filename="package://apc_description/meshes/sdh/knuckle.dae"/>
      </geometry>
    </collision>
  </link>
  <joint name="crichton_left_finger_12_joint" type="revolute">
    <origin rpy="0 0 0" xyz="0 0 0.0165"/>
    <parent link="crichton_left_finger_11_link"/>
    <child link="crichton_left_finger_12_link"/>
    <axis xyz="0 1 0"/>
    <dynamics damping="1"/>
    <limit effort="100" lower="-1.570796327" upper="1.570796327" velocity="5"/>
  </joint>
  <link name="crichton_left_finger_12_link">
    <inertial>
      <origin rpy="0 0 0" xyz="0 0 0"/>
      <mass value="0.1"/>
      <inertia ixx="0.01" ixy="0" ixz="0" iyy="0.01" iyz="0" izz="0.01"/>
    </inertial>
    <visual>
      <origin rpy="0 0 0" xyz="0 0 0"/>
      <geometry>
        <mesh filename="package://apc_description/meshes/sdh/finger.dae"/>
      </geometry>
      <material name="Schunk_LightGrey"/>
    </visual>
    <collision>
      <origin rpy="0 0 0" xyz="0 0 0"/>
      <geometry>
        <mesh filename="package://apc_description/meshes/sdh/finger.dae"/>
      </geometry>
    </collision>
  </link>
  <joint name="crichton_left_finger_13_joint" type="revolute">
    <origin rpy="0 0 0" xyz="0 0 0.0865"/>
    <parent link="crichton_left_finger_12_link"/>
    <child link="crichton_left_finger_13_link"/>
    <axis xyz="0 1 0"/>
    <dynamics damping="1"/>
    <limit effort="100" lower="-1.570796327" upper="1.570796327" velocity="5"/>
  </joint>
  <link name="crichton_left_finger_13_link">
    <inertial>
      <origin rpy="0 0 0" xyz="0 0 0"/>
      <mass value="0.1"/>
      <inertia ixx="0.01" ixy="0" ixz="0" iyy="0.01" iyz="0" izz="0.01"/>
    </inertial>
    <visual>
      <origin rpy="0 0 0" xyz="0 0 0"/>
      <geometry>
        <mesh filename="package://apc_description/meshes/sdh/finger_tip.dae"/>
      </geometry>
      <material name="Schunk_LightGrey"/>
    </visual>
    <collision>
      <origin rpy="0 0 0" xyz="0 0 0"/>
      <geometry>
        <mesh filename="package://apc_description/meshes/sdh/finger_tip.dae"/>
      </geometry>
    </collision>
  </link>
  <joint name="crichton_left_finger_21_joint" type="revolute">
    <mimic joint="crichton_left_knuckle_joint" multiplier="1" offset="0"/>
    <origin rpy="0 0 1.5707963265" xyz="-0.033 -0.01905 0.0745"/>
    <parent link="crichton_left_palm_link"/>
    <child link="crichton_left_finger_21_link"/>
    <axis xyz="0 0 -1"/>
    <dynamics damping="1"/>
    <limit effort="100" lower="0" upper="1.570796327" velocity="5"/>
  </joint>
  <link name="crichton_left_finger_21_link">
    <inertial>
      <origin rpy="0 0 0" xyz="0 0 0"/>
      <mass value="0.1"/>
      <inertia ixx="0.01" ixy="0" ixz="0" iyy="0.01" iyz="0" izz="0.01"/>
    </inertial>
    <visual>
      <origin rpy="0 0 0" xyz="0 0 0"/>
      <geometry>
        <mesh filename="package://apc_description/meshes/sdh/knuckle.dae"/>
      </geometry>
      <material name="Schunk_LightGrey"/>
    </visual>
    <collision>
      <origin rpy="0 0 0" xyz="0 0 0"/>
      <geometry>
        <mesh filename="package://apc_description/meshes/sdh/knuckle.dae"/>
      </geometry>
    </collision>
  </link>
  <joint name="crichton_left_finger_22_joint" type="revolute">
    <origin rpy="0 0 0" xyz="0 0 0.0165"/>
    <parent link="crichton_left_finger_21_link"/>
    <child link="crichton_left_finger_22_link"/>
    <axis xyz="0 1 0"/>
    <dynamics damping="1"/>
    <limit effort="100" lower="-1.570796327" upper="1.570796327" velocity="5"/>
  </joint>
  <link name="crichton_left_finger_22_link">
    <inertial>
      <origin rpy="0 0 0" xyz="0 0 0"/>
      <mass value="0.1"/>
      <inertia ixx="0.01" ixy="0" ixz="0" iyy="0.01" iyz="0" izz="0.01"/>
    </inertial>
    <visual>
      <origin rpy="0 0 0" xyz="0 0 0"/>
      <geometry>
        <mesh filename="package://apc_description/meshes/sdh/finger.dae"/>
      </geometry>
      <material name="Schunk_LightGrey"/>
    </visual>
    <collision>
      <origin rpy="0 0 0" xyz="0 0 0"/>
      <geometry>
        <mesh filename="package://apc_description/meshes/sdh/finger.dae"/>
      </geometry>
    </collision>
  </link>
  <joint name="crichton_left_finger_23_joint" type="revolute">
    <origin rpy="0 0 0" xyz="0 0 0.0865"/>
    <parent link="crichton_left_finger_22_link"/>
    <child link="crichton_left_finger_23_link"/>
    <axis xyz="0 1 0"/>
    <dynamics damping="1"/>
    <limit effort="100" lower="-1.570796327" upper="1.570796327" velocity="5"/>
  </joint>
  <link name="crichton_left_finger_23_link">
    <inertial>
      <origin rpy="0 0 0" xyz="0 0 0"/>
      <mass value="0.1"/>
      <inertia ixx="0.01" ixy="0" ixz="0" iyy="0.01" iyz="0" izz="0.01"/>
    </inertial>
    <visual>
      <origin rpy="0 0 0" xyz="0 0 0"/>
      <geometry>
        <mesh filename="package://apc_description/meshes/sdh/finger_tip.dae"/>
      </geometry>
      <material name="Schunk_LightGrey"/>
    </visual>
    <collision>
      <origin rpy="0 0 0" xyz="0 0 0"/>
      <geometry>
        <mesh filename="package://apc_description/meshes/sdh/finger_tip.dae"/>
      </geometry>
    </collision>
  </link>
  <joint name="crichton_left_thumb_1_joint" type="fixed">
    <origin rpy="0 0 -1.5708" xyz="0 0.03811 0.0745 "/>
    <parent link="crichton_left_palm_link"/>
    <child link="crichton_left_thumb_1_link"/>
  </joint>
  <link name="crichton_left_thumb_1_link">
    <inertial>
      <origin rpy="0 0 0" xyz="0 0 0"/>
      <mass value="0.1"/>
      <inertia ixx="0.01" ixy="0" ixz="0" iyy="0.01" iyz="0" izz="0.01"/>
    </inertial>
    <visual>
      <origin rpy="0 0 0" xyz="0 0 0"/>
      <geometry>
        <mesh filename="package://apc_description/meshes/sdh/knuckle.dae"/>
      </geometry>
      <material name="Schunk_LightGrey"/>
    </visual>
    <collision>
      <origin rpy="0 0 0" xyz="0 0 0"/>
      <geometry>
        <mesh filename="package://apc_description/meshes/sdh/knuckle.dae"/>
      </geometry>
    </collision>
  </link>
  <joint name="crichton_left_thumb_2_joint" type="revolute">
    <origin rpy="0 0 0" xyz="0 0 0.0165"/>
    <parent link="crichton_left_thumb_1_link"/>
    <child link="crichton_left_thumb_2_link"/>
    <axis xyz="0 1 0"/>
    <dynamics damping="1"/>
    <limit effort="100" lower="-1.570796327" upper="1.570796327" velocity="5"/>
  </joint>
  <link name="crichton_left_thumb_2_link">
    <inertial>
      <origin rpy="0 0 0" xyz="0 0 0"/>
      <mass value="0.1"/>
      <inertia ixx="0.01" ixy="0" ixz="0" iyy="0.01" iyz="0" izz="0.01"/>
    </inertial>
    <visual>
      <origin rpy="0 0 0" xyz="0 0 0"/>
      <geometry>
        <mesh filename="package://apc_description/meshes/sdh/finger.dae"/>
      </geometry>
      <material name="Schunk_LightGrey"/>
    </visual>
    <collision>
      <origin rpy="0 0 0" xyz="0 0 0"/>
      <geometry>
        <mesh filename="package://apc_description/meshes/sdh/finger.dae"/>
      </geometry>
    </collision>
  </link>
  <joint name="crichton_left_thumb_3_joint" type="revolute">
    <origin rpy="0 0 0" xyz="0 0 0.0865"/>
    <parent link="crichton_left_thumb_2_link"/>
    <child link="crichton_left_thumb_3_link"/>
    <axis xyz="0 1 0"/>
    <dynamics damping="1"/>
    <limit effort="100" lower="-1.570796327" upper="1.570796327" velocity="5"/>
  </joint>
  <link name="crichton_left_thumb_3_link">
    <inertial>
      <origin rpy="0 0 0" xyz="0 0 0"/>
      <mass value="0.1"/>
      <inertia ixx="0.01" ixy="0" ixz="0" iyy="0.01" iyz="0" izz="0.01"/>
    </inertial>
    <visual>
      <origin rpy="0 0 0" xyz="0 0 0"/>
      <geometry>
        <mesh filename="package://apc_description/meshes/sdh/finger_tip.dae"/>
      </geometry>
      <material name="Schunk_LightGrey"/>
    </visual>
    <collision>
      <origin rpy="0 0 0" xyz="0 0 0"/>
      <geometry>
        <mesh filename="package://apc_description/meshes/sdh/finger_tip.dae"/>
      </geometry>
    </collision>
  </link>
  <gazebo reference="crichton_left_palm_link">
    <gravity>true</gravity>
    <self_collide>false</self_collide>
    <material>Schunk/LightGrey</material>
  </gazebo>
  <gazebo reference="crichton_left_finger_11_link">
    <gravity>true</gravity>
    <self_collide>false</self_collide>
    <material>Schunk/LightGrey</material>
  </gazebo>
  <gazebo reference="crichton_left_finger_12_link">
    <gravity>true</gravity>
    <self_collide>false</self_collide>
    <material>Schunk/LightGrey</material>
    <sensor name="crichton_left_finger_12_contact_sensor" type="contact">
      <always_on>true</always_on>
      <update_rate>100</update_rate>
      <contact>
        <collision>crichton_left_finger_12_link_collision</collision>
        <topic>crichton_left_finger_12_bumper</topic>
      </contact>
      <plugin filename="libgazebo_ros_bumper.so" name="crichton_left_finger_12_gazebo_ros_bumper_controller">
        <frameName>crichton_left_finger_12_link</frameName>
        <bumperTopicName>crichton_left_finger_12_bumper</bumperTopicName>
      </plugin>
    </sensor>
  </gazebo>
  <gazebo reference="crichton_left_finger_13_link">
    <gravity>true</gravity>
    <self_collide>false</self_collide>
    <material>Schunk/LightGrey</material>
    <sensor name="crichton_left_finger_13_contact_sensor" type="contact">
      <always_on>true</always_on>
      <update_rate>100</update_rate>
      <contact>
        <collision>crichton_left_finger_13_link_collision</collision>
        <topic>crichton_left_finger_13_bumper</topic>
      </contact>
      <plugin filename="libgazebo_ros_bumper.so" name="crichton_left_finger_13_gazebo_ros_bumper_controller">
        <frameName>crichton_left_finger_13_link</frameName>
        <bumperTopicName>crichton_left_finger_13_bumper</bumperTopicName>
      </plugin>
    </sensor>
  </gazebo>
  <gazebo reference="crichton_left_finger_21_link">
    <gravity>true</gravity>
    <self_collide>false</self_collide>
    <material>Schunk/LightGrey</material>
    <!--mu1 value="500" />
      <mu2 value="500" />
      <kp value="1000000.0" />
      <kd value="1.0" /-->
  </gazebo>
  <gazebo reference="crichton_left_finger_22_link">
    <gravity>true</gravity>
    <self_collide>false</self_collide>
    <material>Schunk/LightGrey</material>
    <sensor name="crichton_left_finger_22_contact_sensor" type="contact">
      <always_on>true</always_on>
      <update_rate>100</update_rate>
      <contact>
        <collision>crichton_left_finger_22_link_collision</collision>
        <topic>crichton_left_finger_22_bumper</topic>
      </contact>
      <plugin filename="libgazebo_ros_bumper.so" name="crichton_left_finger_22_gazebo_ros_bumper_controller">
        <frameName>crichton_left_finger_22_link</frameName>
        <bumperTopicName>crichton_left_finger_22_bumper</bumperTopicName>
      </plugin>
    </sensor>
  </gazebo>
  <gazebo reference="crichton_left_finger_23_link">
    <gravity>true</gravity>
    <self_collide>false</self_collide>
    <material>Schunk/LightGrey</material>
    <sensor name="crichton_left_finger_23_contact_sensor" type="contact">
      <always_on>true</always_on>
      <update_rate>100</update_rate>
      <contact>
        <collision>crichton_left_finger_23_link_collision</collision>
        <topic>crichton_left_finger_23_bumper</topic>
      </contact>
      <plugin filename="libgazebo_ros_bumper.so" name="crichton_left_finger_23_gazebo_ros_bumper_controller">
        <frameName>crichton_left_finger_23_link</frameName>
        <bumperTopicName>crichton_left_finger_23_bumper</bumperTopicName>
      </plugin>
    </sensor>
  </gazebo>
  <gazebo reference="crichton_left_thumb_1_link">
    <gravity>true</gravity>
    <self_collide>false</self_collide>
    <material>Schunk/LightGrey</material>
  </gazebo>
  <gazebo reference="crichton_left_thumb_2_link">
    <gravity>true</gravity>
    <self_collide>false</self_collide>
    <material>Schunk/LightGrey</material>
    <sensor name="crichton_left_thumb_2_contact_sensor" type="contact">
      <always_on>true</always_on>
      <update_rate>100</update_rate>
      <contact>
        <collision>crichton_left_thumb_2_link_collision</collision>
        <topic>crichton_left_thumb_2_bumper</topic>
      </contact>
      <plugin filename="libgazebo_ros_bumper.so" name="crichton_left_thumb_2_gazebo_ros_bumper_controller">
        <frameName>crichton_left_thumb_2_link</frameName>
        <bumperTopicName>crichton_left_thumb_2_bumper</bumperTopicName>
      </plugin>
    </sensor>
  </gazebo>
  <gazebo reference="crichton_left_thumb_3_link">
    <gravity>true</gravity>
    <self_collide>false</self_collide>
    <material>Schunk/LightGrey</material>
    <sensor name="crichton_left_thumb_3_contact_sensor" type="contact">
      <always_on>true</always_on>
      <update_rate>100</update_rate>
      <contact>
        <collision>crichton_left_thumb_3_link_collision</collision>
        <topic>crichton_left_thumb_3_bumper</topic>
      </contact>
      <plugin filename="libgazebo_ros_bumper.so" name="crichton_left_thumb_3_gazebo_ros_bumper_controller">
        <frameName>crichton_left_thumb_3_link</frameName>
        <bumperTopicName>crichton_left_thumb_3_bumper</bumperTopicName>
      </plugin>
    </sensor>
  </gazebo>
  <transmission name="crichton_left_knuckle_trans">
    <type>transmission_interface/SimpleTransmission</type>
    <joint name="crichton_left_finger_21_joint">
      <hardwareInterface>EffortJointInterface</hardwareInterface>
    </joint>
    <actuator name="crichton_left_knuckle_motor">
      <mechanicalReduction>1</mechanicalReduction>
    </actuator>
  </transmission>
  <transmission name="crichton_left_knuckle_trans">
    <type>transmission_interface/SimpleTransmission</type>
    <joint name="crichton_left_knuckle_joint">
      <hardwareInterface>EffortJointInterface</hardwareInterface>
    </joint>
    <actuator name="crichton_left_knuckle_motor">
      <mechanicalReduction>1</mechanicalReduction>
    </actuator>
  </transmission>
  <transmission name="crichton_left_finger_12_trans">
    <type>transmission_interface/SimpleTransmission</type>
    <joint name="crichton_left_finger_12_joint">
      <hardwareInterface>EffortJointInterface</hardwareInterface>
    </joint>
    <actuator name="crichton_left_finger_12_motor">
      <mechanicalReduction>1</mechanicalReduction>
    </actuator>
  </transmission>
  <transmission name="crichton_left_finger_13_trans">
    <type>transmission_interface/SimpleTransmission</type>
    <joint name="crichton_left_finger_13_joint">
      <hardwareInterface>EffortJointInterface</hardwareInterface>
    </joint>
    <actuator name="crichton_left_finger_13_motor">
      <mechanicalReduction>1</mechanicalReduction>
    </actuator>
  </transmission>
  <transmission name="crichton_left_finger_22_trans">
    <type>transmission_interface/SimpleTransmission</type>
    <joint name="crichton_left_finger_22_joint">
      <hardwareInterface>EffortJointInterface</hardwareInterface>
    </joint>
    <actuator name="crichton_left_finger_22_motor">
      <mechanicalReduction>1</mechanicalReduction>
    </actuator>
  </transmission>
  <transmission name="crichton_left_finger_23_trans">
    <type>transmission_interface/SimpleTransmission</type>
    <joint name="crichton_left_finger_23_joint">
      <hardwareInterface>EffortJointInterface</hardwareInterface>
    </joint>
    <actuator name="crichton_left_finger_23_motor">
      <mechanicalReduction>1</mechanicalReduction>
    </actuator>
  </transmission>
  <transmission name="crichton_left_thumb_2_trans">
    <type>transmission_interface/SimpleTransmission</type>
    <joint name="crichton_left_thumb_2_joint">
      <hardwareInterface>EffortJointInterface</hardwareInterface>
    </joint>
    <actuator name="crichton_left_thumb_2_motor">
      <mechanicalReduction>1</mechanicalReduction>
    </actuator>
  </transmission>
  <transmission name="crichton_left_thumb_3_trans">
    <type>transmission_interface/SimpleTransmission</type>
    <joint name="crichton_left_thumb_3_joint">
      <hardwareInterface>EffortJointInterface</hardwareInterface>
    </joint>
    <actuator name="crichton_left_thumb_3_motor">
      <mechanicalReduction>1</mechanicalReduction>
    </actuator>
  </transmission>
  <joint name="crichton_right_palm_joint" type="fixed">
    <origin rpy="0 3.141592653 -0.5235987755" xyz="0 0 0"/>
    <parent link="crichton_right_7_link"/>
    <child link="crichton_right_palm_link"/>
  </joint>
  <link name="crichton_right_palm_link">
    <inertial>
      <origin rpy="0 0 0" xyz="0 0 0"/>
      <mass value="1"/>
      <inertia ixx="0.01" ixy="0" ixz="0" iyy="0.01" iyz="0" izz="0.01"/>
    </inertial>
    <visual>
      <origin rpy="0 0 0" xyz="0 0 0"/>
      <geometry>
        <mesh filename="package://apc_description/meshes/sdh/palm.dae"/>
      </geometry>
      <material name="Schunk_LightGrey">
        <color rgba="0.7 0.7 0.7 1.0"/>
      </material>
    </visual>
    <collision>
      <origin rpy="0 0 0" xyz="0 0 0"/>
      <geometry>
        <mesh filename="package://apc_description/meshes/sdh/palm.dae"/>
      </geometry>
    </collision>
  </link>
  <joint name="crichton_right_grasp_joint" type="fixed">
    <origin rpy="0 0 0" xyz="0 0 0.15"/>
    <parent link="crichton_right_palm_link"/>
    <child link="crichton_right_grasp_link"/>
  </joint>
  <link name="crichton_right_grasp_link"/>
  <joint name="crichton_right_tip_joint" type="fixed">
    <origin rpy="0 0 0" xyz="0 0 0.22"/>
    <parent link="crichton_right_palm_link"/>
    <child link="crichton_right_tip_link"/>
  </joint>
  <link name="crichton_right_tip_link"/>
  <joint name="crichton_right_knuckle_joint" type="revolute">
    <!-- <origin xyz="-0.033 -0.01905 0.0745" rpy="0 0 ${-M_PI/2}" /> -->
    <origin rpy="0 0 1.5707963265" xyz="0.033 -0.01905 0.0745"/>
    <parent link="crichton_right_palm_link"/>
    <child link="crichton_right_finger_11_link"/>
    <axis xyz="0 0 1"/>
    <dynamics damping="1"/>
    <limit effort="100" lower="0" upper="1.570796327" velocity="5"/>
  </joint>
  <link name="crichton_right_finger_11_link">
    <inertial>
      <origin rpy="0 0 0" xyz="0 0 0"/>
      <mass value="0.1"/>
      <inertia ixx="0.01" ixy="0" ixz="0" iyy="0.01" iyz="0" izz="0.01"/>
    </inertial>
    <visual>
      <origin rpy="0 0 0" xyz="0 0 0"/>
      <geometry>
        <mesh filename="package://apc_description/meshes/sdh/knuckle.dae"/>
      </geometry>
      <material name="Schunk_LightGrey"/>
    </visual>
    <collision>
      <origin rpy="0 0 0" xyz="0 0 0"/>
      <geometry>
        <mesh filename="package://apc_description/meshes/sdh/knuckle.dae"/>
      </geometry>
    </collision>
  </link>
  <joint name="crichton_right_finger_12_joint" type="revolute">
    <origin rpy="0 0 0" xyz="0 0 0.0165"/>
    <parent link="crichton_right_finger_11_link"/>
    <child link="crichton_right_finger_12_link"/>
    <axis xyz="0 1 0"/>
    <dynamics damping="1"/>
    <limit effort="100" lower="-1.570796327" upper="1.570796327" velocity="5"/>
  </joint>
  <link name="crichton_right_finger_12_link">
    <inertial>
      <origin rpy="0 0 0" xyz="0 0 0"/>
      <mass value="0.1"/>
      <inertia ixx="0.01" ixy="0" ixz="0" iyy="0.01" iyz="0" izz="0.01"/>
    </inertial>
    <visual>
      <origin rpy="0 0 0" xyz="0 0 0"/>
      <geometry>
        <mesh filename="package://apc_description/meshes/sdh/finger.dae"/>
      </geometry>
      <material name="Schunk_LightGrey"/>
    </visual>
    <collision>
      <origin rpy="0 0 0" xyz="0 0 0"/>
      <geometry>
        <mesh filename="package://apc_description/meshes/sdh/finger.dae"/>
      </geometry>
    </collision>
  </link>
  <joint name="crichton_right_finger_13_joint" type="revolute">
    <origin rpy="0 0 0" xyz="0 0 0.0865"/>
    <parent link="crichton_right_finger_12_link"/>
    <child link="crichton_right_finger_13_link"/>
    <axis xyz="0 1 0"/>
    <dynamics damping="1"/>
    <limit effort="100" lower="-1.570796327" upper="1.570796327" velocity="5"/>
  </joint>
  <link name="crichton_right_finger_13_link">
    <inertial>
      <origin rpy="0 0 0" xyz="0 0 0"/>
      <mass value="0.1"/>
      <inertia ixx="0.01" ixy="0" ixz="0" iyy="0.01" iyz="0" izz="0.01"/>
    </inertial>
    <visual>
      <origin rpy="0 0 0" xyz="0 0 0"/>
      <geometry>
        <mesh filename="package://apc_description/meshes/sdh/finger_tip.dae"/>
      </geometry>
      <material name="Schunk_LightGrey"/>
    </visual>
    <collision>
      <origin rpy="0 0 0" xyz="0 0 0"/>
      <geometry>
        <mesh filename="package://apc_description/meshes/sdh/finger_tip.dae"/>
      </geometry>
    </collision>
  </link>
  <joint name="crichton_right_finger_21_joint" type="revolute">
    <mimic joint="crichton_right_knuckle_joint" multiplier="1" offset="0"/>
    <origin rpy="0 0 1.5707963265" xyz="-0.033 -0.01905 0.0745"/>
    <parent link="crichton_right_palm_link"/>
    <child link="crichton_right_finger_21_link"/>
    <axis xyz="0 0 -1"/>
    <dynamics damping="1"/>
    <limit effort="100" lower="0" upper="1.570796327" velocity="5"/>
  </joint>
  <link name="crichton_right_finger_21_link">
    <inertial>
      <origin rpy="0 0 0" xyz="0 0 0"/>
      <mass value="0.1"/>
      <inertia ixx="0.01" ixy="0" ixz="0" iyy="0.01" iyz="0" izz="0.01"/>
    </inertial>
    <visual>
      <origin rpy="0 0 0" xyz="0 0 0"/>
      <geometry>
        <mesh filename="package://apc_description/meshes/sdh/knuckle.dae"/>
      </geometry>
      <material name="Schunk_LightGrey"/>
    </visual>
    <collision>
      <origin rpy="0 0 0" xyz="0 0 0"/>
      <geometry>
        <mesh filename="package://apc_description/meshes/sdh/knuckle.dae"/>
      </geometry>
    </collision>
  </link>
  <joint name="crichton_right_finger_22_joint" type="revolute">
    <origin rpy="0 0 0" xyz="0 0 0.0165"/>
    <parent link="crichton_right_finger_21_link"/>
    <child link="crichton_right_finger_22_link"/>
    <axis xyz="0 1 0"/>
    <dynamics damping="1"/>
    <limit effort="100" lower="-1.570796327" upper="1.570796327" velocity="5"/>
  </joint>
  <link name="crichton_right_finger_22_link">
    <inertial>
      <origin rpy="0 0 0" xyz="0 0 0"/>
      <mass value="0.1"/>
      <inertia ixx="0.01" ixy="0" ixz="0" iyy="0.01" iyz="0" izz="0.01"/>
    </inertial>
    <visual>
      <origin rpy="0 0 0" xyz="0 0 0"/>
      <geometry>
        <mesh filename="package://apc_description/meshes/sdh/finger.dae"/>
      </geometry>
      <material name="Schunk_LightGrey"/>
    </visual>
    <collision>
      <origin rpy="0 0 0" xyz="0 0 0"/>
      <geometry>
        <mesh filename="package://apc_description/meshes/sdh/finger.dae"/>
      </geometry>
    </collision>
  </link>
  <joint name="crichton_right_finger_23_joint" type="revolute">
    <origin rpy="0 0 0" xyz="0 0 0.0865"/>
    <parent link="crichton_right_finger_22_link"/>
    <child link="crichton_right_finger_23_link"/>
    <axis xyz="0 1 0"/>
    <dynamics damping="1"/>
    <limit effort="100" lower="-1.570796327" upper="1.570796327" velocity="5"/>
  </joint>
  <link name="crichton_right_finger_23_link">
    <inertial>
      <origin rpy="0 0 0" xyz="0 0 0"/>
      <mass value="0.1"/>
      <inertia ixx="0.01" ixy="0" ixz="0" iyy="0.01" iyz="0" izz="0.01"/>
    </inertial>
    <visual>
      <origin rpy="0 0 0" xyz="0 0 0"/>
      <geometry>
        <mesh filename="package://apc_description/meshes/sdh/finger_tip.dae"/>
      </geometry>
      <material name="Schunk_LightGrey"/>
    </visual>
    <collision>
      <origin rpy="0 0 0" xyz="0 0 0"/>
      <geometry>
        <mesh filename="package://apc_description/meshes/sdh/finger_tip.dae"/>
      </geometry>
    </collision>
  </link>
  <joint name="crichton_right_thumb_1_joint" type="fixed">
    <origin rpy="0 0 -1.5708" xyz="0 0.03811 0.0745 "/>
    <parent link="crichton_right_palm_link"/>
    <child link="crichton_right_thumb_1_link"/>
  </joint>
  <link name="crichton_right_thumb_1_link">
    <inertial>
      <origin rpy="0 0 0" xyz="0 0 0"/>
      <mass value="0.1"/>
      <inertia ixx="0.01" ixy="0" ixz="0" iyy="0.01" iyz="0" izz="0.01"/>
    </inertial>
    <visual>
      <origin rpy="0 0 0" xyz="0 0 0"/>
      <geometry>
        <mesh filename="package://apc_description/meshes/sdh/knuckle.dae"/>
      </geometry>
      <material name="Schunk_LightGrey"/>
    </visual>
    <collision>
      <origin rpy="0 0 0" xyz="0 0 0"/>
      <geometry>
        <mesh filename="package://apc_description/meshes/sdh/knuckle.dae"/>
      </geometry>
    </collision>
  </link>
  <joint name="crichton_right_thumb_2_joint" type="revolute">
    <origin rpy="0 0 0" xyz="0 0 0.0165"/>
    <parent link="crichton_right_thumb_1_link"/>
    <child link="crichton_right_thumb_2_link"/>
    <axis xyz="0 1 0"/>
    <dynamics damping="1"/>
    <limit effort="100" lower="-1.570796327" upper="1.570796327" velocity="5"/>
  </joint>
  <link name="crichton_right_thumb_2_link">
    <inertial>
      <origin rpy="0 0 0" xyz="0 0 0"/>
      <mass value="0.1"/>
      <inertia ixx="0.01" ixy="0" ixz="0" iyy="0.01" iyz="0" izz="0.01"/>
    </inertial>
    <visual>
      <origin rpy="0 0 0" xyz="0 0 0"/>
      <geometry>
        <mesh filename="package://apc_description/meshes/sdh/finger.dae"/>
      </geometry>
      <material name="Schunk_LightGrey"/>
    </visual>
    <collision>
      <origin rpy="0 0 0" xyz="0 0 0"/>
      <geometry>
        <mesh filename="package://apc_description/meshes/sdh/finger.dae"/>
      </geometry>
    </collision>
  </link>
  <joint name="crichton_right_thumb_3_joint" type="revolute">
    <origin rpy="0 0 0" xyz="0 0 0.0865"/>
    <parent link="crichton_right_thumb_2_link"/>
    <child link="crichton_right_thumb_3_link"/>
    <axis xyz="0 1 0"/>
    <dynamics damping="1"/>
    <limit effort="100" lower="-1.570796327" upper="1.570796327" velocity="5"/>
  </joint>
  <link name="crichton_right_thumb_3_link">
    <inertial>
      <origin rpy="0 0 0" xyz="0 0 0"/>
      <mass value="0.1"/>
      <inertia ixx="0.01" ixy="0" ixz="0" iyy="0.01" iyz="0" izz="0.01"/>
    </inertial>
    <visual>
      <origin rpy="0 0 0" xyz="0 0 0"/>
      <geometry>
        <mesh filename="package://apc_description/meshes/sdh/finger_tip.dae"/>
      </geometry>
      <material name="Schunk_LightGrey"/>
    </visual>
    <collision>
      <origin rpy="0 0 0" xyz="0 0 0"/>
      <geometry>
        <mesh filename="package://apc_description/meshes/sdh/finger_tip.dae"/>
      </geometry>
    </collision>
  </link>
  <gazebo reference="crichton_right_palm_link">
    <gravity>true</gravity>
    <self_collide>false</self_collide>
    <material>Schunk/LightGrey</material>
  </gazebo>
  <gazebo reference="crichton_right_finger_11_link">
    <gravity>true</gravity>
    <self_collide>false</self_collide>
    <material>Schunk/LightGrey</material>
  </gazebo>
  <gazebo reference="crichton_right_finger_12_link">
    <gravity>true</gravity>
    <self_collide>false</self_collide>
    <material>Schunk/LightGrey</material>
    <sensor name="crichton_right_finger_12_contact_sensor" type="contact">
      <always_on>true</always_on>
      <update_rate>100</update_rate>
      <contact>
        <collision>crichton_right_finger_12_link_collision</collision>
        <topic>crichton_right_finger_12_bumper</topic>
      </contact>
      <plugin filename="libgazebo_ros_bumper.so" name="crichton_right_finger_12_gazebo_ros_bumper_controller">
        <frameName>crichton_right_finger_12_link</frameName>
        <bumperTopicName>crichton_right_finger_12_bumper</bumperTopicName>
      </plugin>
    </sensor>
  </gazebo>
  <gazebo reference="crichton_right_finger_13_link">
    <gravity>true</gravity>
    <self_collide>false</self_collide>
    <material>Schunk/LightGrey</material>
    <sensor name="crichton_right_finger_13_contact_sensor" type="contact">
      <always_on>true</always_on>
      <update_rate>100</update_rate>
      <contact>
        <collision>crichton_right_finger_13_link_collision</collision>
        <topic>crichton_right_finger_13_bumper</topic>
      </contact>
      <plugin filename="libgazebo_ros_bumper.so" name="crichton_right_finger_13_gazebo_ros_bumper_controller">
        <frameName>crichton_right_finger_13_link</frameName>
        <bumperTopicName>crichton_right_finger_13_bumper</bumperTopicName>
      </plugin>
    </sensor>
  </gazebo>
  <gazebo reference="crichton_right_finger_21_link">
    <gravity>true</gravity>
    <self_collide>false</self_collide>
    <material>Schunk/LightGrey</material>
    <!--mu1 value="500" />
      <mu2 value="500" />
      <kp value="1000000.0" />
      <kd value="1.0" /-->
  </gazebo>
  <gazebo reference="crichton_right_finger_22_link">
    <gravity>true</gravity>
    <self_collide>false</self_collide>
    <material>Schunk/LightGrey</material>
    <sensor name="crichton_right_finger_22_contact_sensor" type="contact">
      <always_on>true</always_on>
      <update_rate>100</update_rate>
      <contact>
        <collision>crichton_right_finger_22_link_collision</collision>
        <topic>crichton_right_finger_22_bumper</topic>
      </contact>
      <plugin filename="libgazebo_ros_bumper.so" name="crichton_right_finger_22_gazebo_ros_bumper_controller">
        <frameName>crichton_right_finger_22_link</frameName>
        <bumperTopicName>crichton_right_finger_22_bumper</bumperTopicName>
      </plugin>
    </sensor>
  </gazebo>
  <gazebo reference="crichton_right_finger_23_link">
    <gravity>true</gravity>
    <self_collide>false</self_collide>
    <material>Schunk/LightGrey</material>
    <sensor name="crichton_right_finger_23_contact_sensor" type="contact">
      <always_on>true</always_on>
      <update_rate>100</update_rate>
      <contact>
        <collision>crichton_right_finger_23_link_collision</collision>
        <topic>crichton_right_finger_23_bumper</topic>
      </contact>
      <plugin filename="libgazebo_ros_bumper.so" name="crichton_right_finger_23_gazebo_ros_bumper_controller">
        <frameName>crichton_right_finger_23_link</frameName>
        <bumperTopicName>crichton_right_finger_23_bumper</bumperTopicName>
      </plugin>
    </sensor>
  </gazebo>
  <gazebo reference="crichton_right_thumb_1_link">
    <gravity>true</gravity>
    <self_collide>false</self_collide>
    <material>Schunk/LightGrey</material>
  </gazebo>
  <gazebo reference="crichton_right_thumb_2_link">
    <gravity>true</gravity>
    <self_collide>false</self_collide>
    <material>Schunk/LightGrey</material>
    <sensor name="crichton_right_thumb_2_contact_sensor" type="contact">
      <always_on>true</always_on>
      <update_rate>100</update_rate>
      <contact>
        <collision>crichton_right_thumb_2_link_collision</collision>
        <topic>crichton_right_thumb_2_bumper</topic>
      </contact>
      <plugin filename="libgazebo_ros_bumper.so" name="crichton_right_thumb_2_gazebo_ros_bumper_controller">
        <frameName>crichton_right_thumb_2_link</frameName>
        <bumperTopicName>crichton_right_thumb_2_bumper</bumperTopicName>
      </plugin>
    </sensor>
  </gazebo>
  <gazebo reference="crichton_right_thumb_3_link">
    <gravity>true</gravity>
    <self_collide>false</self_collide>
    <material>Schunk/LightGrey</material>
    <sensor name="crichton_right_thumb_3_contact_sensor" type="contact">
      <always_on>true</always_on>
      <update_rate>100</update_rate>
      <contact>
        <collision>crichton_right_thumb_3_link_collision</collision>
        <topic>crichton_right_thumb_3_bumper</topic>
      </contact>
      <plugin filename="libgazebo_ros_bumper.so" name="crichton_right_thumb_3_gazebo_ros_bumper_controller">
        <frameName>crichton_right_thumb_3_link</frameName>
        <bumperTopicName>crichton_right_thumb_3_bumper</bumperTopicName>
      </plugin>
    </sensor>
  </gazebo>
  <transmission name="crichton_right_knuckle_trans">
    <type>transmission_interface/SimpleTransmission</type>
    <joint name="crichton_right_finger_21_joint">
      <hardwareInterface>EffortJointInterface</hardwareInterface>
    </joint>
    <actuator name="crichton_right_knuckle_motor">
      <mechanicalReduction>1</mechanicalReduction>
    </actuator>
  </transmission>
  <transmission name="crichton_right_knuckle_trans">
    <type>transmission_interface/SimpleTransmission</type>
    <joint name="crichton_right_knuckle_joint">
      <hardwareInterface>EffortJointInterface</hardwareInterface>
    </joint>
    <actuator name="crichton_right_knuckle_motor">
      <mechanicalReduction>1</mechanicalReduction>
    </actuator>
  </transmission>
  <transmission name="crichton_right_finger_12_trans">
    <type>transmission_interface/SimpleTransmission</type>
    <joint name="crichton_right_finger_12_joint">
      <hardwareInterface>EffortJointInterface</hardwareInterface>
    </joint>
    <actuator name="crichton_right_finger_12_motor">
      <mechanicalReduction>1</mechanicalReduction>
    </actuator>
  </transmission>
  <transmission name="crichton_right_finger_13_trans">
    <type>transmission_interface/SimpleTransmission</type>
    <joint name="crichton_right_finger_13_joint">
      <hardwareInterface>EffortJointInterface</hardwareInterface>
    </joint>
    <actuator name="crichton_right_finger_13_motor">
      <mechanicalReduction>1</mechanicalReduction>
    </actuator>
  </transmission>
  <transmission name="crichton_right_finger_22_trans">
    <type>transmission_interface/SimpleTransmission</type>
    <joint name="crichton_right_finger_22_joint">
      <hardwareInterface>EffortJointInterface</hardwareInterface>
    </joint>
    <actuator name="crichton_right_finger_22_motor">
      <mechanicalReduction>1</mechanicalReduction>
    </actuator>
  </transmission>
  <transmission name="crichton_right_finger_23_trans">
    <type>transmission_interface/SimpleTransmission</type>
    <joint name="crichton_right_finger_23_joint">
      <hardwareInterface>EffortJointInterface</hardwareInterface>
    </joint>
    <actuator name="crichton_right_finger_23_motor">
      <mechanicalReduction>1</mechanicalReduction>
    </actuator>
  </transmission>
  <transmission name="crichton_right_thumb_2_trans">
    <type>transmission_interface/SimpleTransmission</type>
    <joint name="crichton_right_thumb_2_joint">
      <hardwareInterface>EffortJointInterface</hardwareInterface>
    </joint>
    <actuator name="crichton_right_thumb_2_motor">
      <mechanicalReduction>1</mechanicalReduction>
    </actuator>
  </transmission>
  <transmission name="crichton_right_thumb_3_trans">
    <type>transmission_interface/SimpleTransmission</type>
    <joint name="crichton_right_thumb_3_joint">
      <hardwareInterface>EffortJointInterface</hardwareInterface>
    </joint>
    <actuator name="crichton_right_thumb_3_motor">
      <mechanicalReduction>1</mechanicalReduction>
    </actuator>
  </transmission>
</robot>

